<?xml version='1.0' encoding='utf-8'?>
<robot xmlns:xacro="http://www.ros.org/wiki/xacro" name="housem8">
    
    <material name="blue">
        <color rgba="0.203125 0.23828125 0.28515625 1.0"/>
    </material>

    <!-- <link name="world">
    </link>

    <link name="map">
    </link>

    <link name="odom">
    </link>

    <link name="imu_link">
    </link> -->

    <link name="base_footprint">
        <pose> 0 0 0 0 0 0</pose>

    </link>

    <link name="mobilebaseI">
        <visual name="mobilebaseI">
            <geometry name = "mobilebaseI">
                <box size="0.200 0.240 0.160"/>
                <origin xyz="0.0 0.0 0.180" rpy="0.0 0.0 0.0"/>
            </geometry>
        </visual>
        <inertial>
            <mass value="2.0"/>
            <inertia ixx="5.0" ixy="0.0" ixz="0.0" 
                     iyy="7.0" iyz="0.0" izz="6.0"/>
        </inertial>
        <collision>
            <origin xyz="0.0 0.0 0.180" rpy="0.0 0.0 0.0"/>
            <geometry name = "mobilebaseI">
                <box size="0.200 0.240 0.160"/>
                
            </geometry>
        </collision>
    </link>

    <!-- <joint name="world_to_map" type="fixed">
        <parent link="world"/>
        <child link="map"/>
        <origin rpy="0 0 0" xyz="0 0 0"/>
    </joint>

    <joint name="map_to_odom" type="fixed">
        <parent link="map"/>
        <child link="odom"/>
        <origin rpy="0 0 0" xyz="0 0 0"/>
    </joint>

    <joint name="odom_to_imu" type="fixed">
        <parent link="odom"/>
        <child link="imu_link"/>
        <origin rpy="0 0 0" xyz="0 0 0"/>
    </joint>

    <joint name="imu_to_basefootprint" type="fixed">
        <parent link="imu_link"/>
        <child link="base_footprint"/>
        <origin rpy="0 0 0" xyz="0 0 0"/>
    </joint>

    <joint name="basefootprint_to_baselink" type="fixed">
        <origin xyz="0 0 0.1" rpy="0 0 0"/>
        <parent link="base_footprint"/>
        <child link="mobilebaseI"/>
    </joint> -->

    <!-- <joint name="world_to_base" type="fixed">
        <parent link="world"/>
        <child link="mobilebaseI"/>
        <origin rpy="0 0 0" xyz="0 0 0.1"/>
    </joint> -->

    <joint name="world_to_base" type="fixed">
        <parent link="base_footprint"/>
        <child link="mobilebaseI"/>
        <origin rpy="0 0 0" xyz="0 0 0.1"/>
    </joint>

    <link name="mobilebaseII">
        <visual name="mobilebaseII">
            <geometry name = "mobilebaseII">
                <box size="0.270 0.400 0.100"/>
                <origin xyz="0.0 0.0 0.00" rpy="0.0 0.0 0.0"/>
            </geometry>
            <!-- <material name="white">
            </material> -->
        </visual>
        <inertial>
            <mass value="18.0"/>
            <inertia ixx="8.0" ixy="0.0" ixz="0.0" 
                     iyy="2.0" iyz="0.0" izz="1.0"/>
        </inertial>
        <collision>
            <origin xyz="0.0 0.0 0.00" rpy="0.0 0.0 0.0"/>
            <geometry name = "mobilebaseII">
                <box size="0.270 0.400 0.100"/>
                
            </geometry>
        </collision>
    </link>

    <joint name="MobileBaseWheel" type="fixed">
        <origin xyz="0.235 0.0 0.110" rpy="0.0 0.0 0.0"/>
        <parent link="mobilebaseI"/>
        <child link="mobilebaseII"/>
    </joint>

    <link name="Wheel_Right">
        <inertial>
            <mass value="1.5"/>
            <inertia ixx="8.0" ixy="0.0" ixz="0.0" 
                     iyy="4.0" iyz="0.0" izz="4.0"/>
        </inertial>
        <visual name="Wheel">
            <origin xyz="0.0 0.0 0.0" rpy="0.0 0.0 0.0"/>
            <geometry name = "wheel">
                <cylinder radius="0.100" length="0.070"/>
            </geometry>
            <!-- <material name="Gray1">
                <color rgba="0.7 0.7 0.7 1.0"/>
            </material> -->
        </visual>
        <collision>
            <origin xyz="0.0 0.0 0.0" rpy="0.0 0.0 0.0"/>
            <geometry name = "wheel">
                <cylinder radius="0.100" length="0.070"/>
                
            </geometry>
        </collision>
    </link>

    <joint name="wheel_right_joint" type="continuous">
        <origin xyz="0.0 0.155 0.005" rpy="1.57 0.0 0.0"/>
        <parent link="mobilebaseI"/>
        <child link="Wheel_Right"/>
        <axis xyz="0 0 1"/>
    </joint>

    <link name="Wheel_Left">
        <inertial>
            <mass value="1.5"/>
            <inertia ixx="8.0" ixy="0.0" ixz="0.0" 
                     iyy="4.0" iyz="0.0" izz="4.0"/>
        </inertial>
        <visual name="Wheel">
            <origin xyz="0.0 0.0 0.0" rpy="0.0 0.0 0.0"/>
            <geometry name = "wheel">
                <cylinder radius="0.100" length="0.070"/>
            </geometry>
            <!-- <material name="Gray1">
                <color rgba="0.7 0.7 0.7 1.0"/>
            </material> -->
        </visual>
        <collision>
            <origin xyz="0.0 0.0 0.0" rpy="0.0 0.0 0.0"/>
            <geometry name = "wheel">
                <cylinder radius="0.100" length="0.070"/>
                
            </geometry>
        </collision>
    </link>

    <joint name="wheel_left_joint" type="continuous">
        <origin xyz="0.0 -0.155 0.005" rpy="1.57 0.0 0.0"/>
        <parent link="mobilebaseI"/>
        <child link="Wheel_Left"/>
        <axis xyz="0 0 1"/>
    </joint>

    <!-- <gazebo reference="wheel_left_joint">
        <mu1>0</mu1>
        <mu2>0</mu2>
        <material>Gazebo/Blue</material>
      </gazebo>
      <gazebo reference="wheel_right_joint">
        <mu1>0</mu1>
        <mu2>0</mu2>
        <material>Gazebo/Blue</material>
      </gazebo> -->

    <link name="CasterCase_Left">
        <inertial>
            <mass value="0.06"/>
            <inertia ixx="0.2" ixy="0.0" ixz="0.0" 
                     iyy="0.6" iyz="-0.7" izz="0.2"/>
        </inertial>
        <visual name="CasterCase">
            <origin xyz="0.0 0.0 -0.005" rpy="0.0 0.0 0.0"/>
            <geometry name = "CasterC">
                <cylinder radius="0.025" length="0.010"/>
            </geometry>
            <!-- <material name="Gray1">
                <color rgba="0.7 0.7 0.7 1.0"/>
            </material> -->
        </visual>
        <collision>
            <origin xyz="0.0 0.0 -0.005" rpy="0.0 0.0 0.0"/>
            <geometry name = "CasterC">
                <cylinder radius="0.025" length="0.010"/>
                
            </geometry>
        </collision>
    </link>

    <joint name="CasterCL" type="fixed">
        <origin xyz="0.040 -0.110 -0.05" rpy="0.0 0.0 0.0"/>
        <parent link="mobilebaseII"/>
        <child link="CasterCase_Left"/>
        <axis xyz="0 0 1"/>
    </joint>

    <link name="CasterWheel_Left">
        <inertial>
            <mass value="0.3"/>
            <inertia ixx="0.6" ixy="0.0" ixz="0.0" 
                     iyy="0.3" iyz="0.0" izz="0.3"/>
        </inertial>
        <visual name="CasterWheel">
            <origin xyz="0.0 0.0 0.0" rpy="0.0 0.0 0.0"/>
            <geometry name = "Casterwheel">
                <cylinder radius="0.0625" length="0.036"/>
            </geometry>
            <!-- <material name="Gray2">
                <color rgba="0.5 0.5 0.5 1.0"/>
            </material> -->
        </visual>
        <collision>
            <origin xyz="0.0 0.0 0.0" rpy="0.0 0.0 0.0"/>
            <geometry name = "Casterwheel">
                <cylinder radius="0.0625" length="0.036"/>
                
            </geometry>
        </collision>
    </link>

    <joint name="Casterwheel_left_joint" type="continuous">
        <origin xyz="0.0405 0.0 -0.0925" rpy="1.57 0.0 0.0"/>
        <parent link="CasterCase_Left"/>
        <child link="CasterWheel_Left"/>
        <axis xyz="0 0 1"/>
        <dynamics damping="0.5" friction="0.2"/>
    </joint>

    <link name="CasterCase_Right">
        <inertial>
            <mass value="0.06"/>
            <inertia ixx="0.2" ixy="0.0" ixz="0.0" 
                     iyy="0.6" iyz="-0.7" izz="0.2"/>
        </inertial>
        <visual name="CasterCase">
            <origin xyz="0.0 0.0 -0.005" rpy="0.0 0.0 0.0"/>
            <geometry name = "CasterC">
                <cylinder radius="0.025" length="0.010"/>
            </geometry>
            <!-- <material name="Gray1">
                <color rgba="0.7 0.7 0.7 1.0"/>
            </material> -->
        </visual>
        <collision>
            <origin xyz="0.0 0.0 -0.005" rpy="0.0 0.0 0.0"/>
            <geometry name = "CasterC">
                <cylinder radius="0.025" length="0.010"/>
                
            </geometry>
        </collision>
    </link>

    <joint name="CasterCR" type="fixed">
        <origin xyz="0.040 0.110 -0.05" rpy="0.0 0.0 0.0"/>
        <parent link="mobilebaseII"/>
        <child link="CasterCase_Right"/>
        <axis xyz="1.0 0.0 0.0"/>
        
    </joint>

    <link name="CasterWheel_Right">
        <inertial>
            <mass value="0.3"/>
            <inertia ixx="0.6" ixy="0.0" ixz="0.0" 
                     iyy="0.3" iyz="0.0" izz="0.3"/>
        </inertial>
        <visual name="CasterWheel">
            <origin xyz="0.0 0.0 0.0" rpy="0.0 0.0 0.0"/>
            <geometry name = "Casterwheel">
                <cylinder radius="0.0625" length="0.036"/>
            </geometry>
            <!-- <material name="Gray2">
                <color rgba="0.5 0.5 0.5 1.0"/>
            </material> -->
        </visual>
        <collision>
            <origin xyz="0.0 0.0 0.0" rpy="0.0 0.0 0.0"/>
            <geometry name = "Casterwheel">
                <cylinder radius="0.0625" length="0.036"/>
                 
            </geometry>
        </collision>
    </link>

    <joint name="Casterwheel_right_joint" type="continuous">
        <origin xyz="0.0405 0.0 -0.0925" rpy="1.57 0.0 0.0"/>
        <parent link="CasterCase_Right"/>
        <child link="CasterWheel_Right"/>
        <axis xyz="0 0 1"/>
        <dynamics damping="0.5" friction="0.2"/>
    </joint>

    <link name="mobilebaseIII">
        <inertial>
            <mass value="10.0"/>
            <inertia ixx="0.6" ixy="0.0" ixz="0.0" 
                     iyy="0.1" iyz="0.0" izz="0.4"/>
        </inertial>
        <visual name = "mobilebaseIII">
            <origin xyz="0.0 0.0 0.0" rpy="0.0 0.0 0.0"/>
            <geometry name = "mobilebaseIII">
                <box size="0.235 0.180 0.030"/>
            </geometry >
            <!-- <material name="white"></material> -->
        </visual>
        <collision>
            <origin xyz="0.0 0.0 0.0" rpy="0.0 0.0 0.0"/>
            <geometry name = "mobilebaseIII">
                <box size="0.235 0.180 0.030"/>
            </geometry >
        </collision>
    </link>

    <joint name="MobileBaseLidar" type="fixed">     
        <origin xyz="-0.100 0.0 0.065" rpy="0.0 0.0 0.0"/>
        <parent link="mobilebaseII"/>
        <child link="mobilebaseIII"/>
        <axis xyz="0 0 1"/>
    </joint>

    <link name="mobilebaseIV">
        <inertial>
            <mass value="1.0"/>
            <inertia ixx="0.2" ixy="0.0" ixz="0.0" 
                     iyy="0.3" iyz="0.0" izz="0.1"/>
        </inertial>
        <visual name = "mobilebaseIII">
            <origin xyz="0.0 0.0 0.0" rpy="0.0 0.0 0.0"/>
            <geometry name = "mobilebaseIV">
                <box size="0.470 0.400 0.045"/>
            </geometry >
            <!-- <material name="white"></material> -->
        </visual>
        <collision>
            <origin xyz="0.0 0.0 0.0" rpy="0.0 0.0 0.0"/>
            <geometry name = "mobilebaseIV">
                <box size="0.470 0.400 0.045"/>
                
            </geometry >
        </collision>
    </link>

    <joint name="MobileBaseTorsol" type="fixed">
        <origin xyz="0.0 0.0 0.0375" rpy="0.0 0.0 0.0"/>
        <parent link="mobilebaseIII"/>
        <child link="mobilebaseIV"/>
    </joint>

    <link name="Lidar_Front">
        <inertial>
            <mass value="0.3"/>
            <inertia ixx="0.4" ixy="0.0" ixz="0.0" 
                     iyy="0.7" iyz="0.0" izz="0.4"/>
        </inertial>
        <visual name="Lidar_Front">
            <origin xyz="0.0 0.0 0.0" rpy="0.0 0.0 0.0"/>
            <geometry name = "Lidar_front">
                <cylinder radius="0.035" length="0.030"/>
            </geometry>
            <!-- <material name="Gray4">
                <color rgba="0.2 0.2 0.2 1.0"/>
            </material> -->
        </visual>
        <collision>
            <origin xyz="0.0 0.0 0.0" rpy="0.0 0.0 0.0"/>
            <geometry name = "Lidar_front">
                <cylinder radius="0.035" length="0.030"/>
                
            </geometry>
        </collision>
    </link>

    <joint name="LidarF" type="fixed">
        <origin xyz="-0.178 0.150 0.0" rpy="0.0 0.0 3.14"/>
        <parent link="mobilebaseIII"/>
        <child link="Lidar_Front"/>
        <axis xyz="1.0 0.0 0.0"/>
    </joint>

    <link name="Lidar_Back">
        <inertial>
            <mass value="0.3"/>
            <inertia ixx="0.4" ixy="0.0" ixz="0.0" 
                     iyy="0.7" iyz="0.0" izz="0.4"/>
        </inertial>
        <visual name="Lidar_Back">
            <origin xyz="0.0 0.0 0.0" rpy="0.0 0.0 0.0"/>
            <geometry name = "Lidar_back">
                <cylinder radius="0.035" length="0.030"/>
            </geometry>
            <!-- <material name="Gray4">
                <color rgba="0.2 0.2 0.2 1.0"/>
            </material> -->
        </visual>
        <collision>
            <origin xyz="0.0 0.0 0.0" rpy="0.0 0.0 0.0"/>
            <geometry name = "Lidar_back">
                <cylinder radius="0.035" length="0.030"/>
                
            </geometry>
        </collision>
    </link>

    <joint name="LidarB" type="fixed">
        <origin xyz="0.178 -0.150 0.0" rpy="0.0 0.0 0.0"/>
        <parent link="mobilebaseIII"/>
        <child link="Lidar_Back"/>
        <axis xyz="1.0 0.0 0.0"/>
    </joint>

    <link name="Torsol">
        <inertial>
            <mass value="0.8"/>
            <inertia ixx="7.0" ixy="5.0" ixz="8.0" 
                     iyy="4.0" iyz="4.0" izz="7.0"/>
        </inertial>
        <visual name="Body">
            <origin xyz="0.0 0.0 0.445" rpy="0.0 0.0 0.0"/>
            <geometry name = "body">
                <box size="0.220 0.285 0.890"/>
            </geometry>
            <!-- <material name="white"></material> -->
        </visual>
        <collision>
            <origin xyz="0.125 0.0 0.445" rpy="0.0 0.0 0.0"/>
            <geometry name = "body">
                <box size="0.220 0.285 0.890"/>
                
            </geometry>
        </collision>
    </link>

    <joint name="BaseTorsol" type="fixed">
        <origin xyz="0.125 -0.0575 0.0225" rpy="0.0 0.0 0.0"/>
        <parent link="mobilebaseIV"/>
        <child link="Torsol"/>
    </joint>

    <!-- <link name="TorsolCamera">
        <inertial>
            <mass value="0.2"/>
            <inertia ixx="0.6" ixy="0.0" ixz="0.0" 
                     iyy="0.1" iyz="0.0" izz="0.1"/>
        </inertial>
        <visual name="Camera">
            <origin xyz="0.0 0.0 0.89" rpy="0.0 0.0 0.0"/>
            <geometry name = "Camera">
                <box size="0.03 0.08 0.03"/>
            </geometry>
            <material name="black"></material>
        </visual>
        <collision>
            <geometry name = "Camera">
                <box size="0.03 0.08 0.03"/>
            </geometry>
        </collision>
    </link>

    <joint name="BodyCam" type="revolute">
        <origin xyz="0.050 0.0 0.9525" rpy="0.0 0.0 0.0"/>
        <parent link="mobilebaseIV"/>
        <child link="TorsolCamera"/>
        <axis xyz="0.0 1.0 0.0"/>
       
    </joint> -->


    <link name="LinearJoint">
        <inertial>
            <mass value="0.5"/>
            <inertia ixx="7.0" ixy="-5.0" ixz="8.0" 
                     iyy="4.0" iyz="4.0" izz="7.0"/>
        </inertial>
        <visual>
            <origin xyz="0.0 0.0 0.0" rpy="0.0 0.0 0.0"/>
            <geometry name = "LinearJoint">
                <cylinder radius="0.080" length="0.050"/>
            </geometry>
        </visual>
        <collision>
            <origin xyz="0.0 0.0 0.0" rpy="0.0 0.0 0.0"/>
            <geometry name = "LinearJoint">
                <cylinder radius="0.080" length="0.050"/>
                
            </geometry>
        </collision>
    </link>

    <joint name="Mani_J0" type="prismatic">
        <origin xyz="0.0 0.0 0.0275" rpy="0.0 0.0 0.0"/>
        <parent link="mobilebaseIV"/>
        <child link="LinearJoint"/>
        <axis xyz="0 0 1"/>
        <limit lower="0.0" upper="0.650" effort="87.0" velocity="2.15"/>
        <dynamics damping="0.5" friction="0.2"/>
    </joint>

    <link name="Revlink1">
        <inertial>
            <mass value="0.1"/>
            <inertia ixx="0.4" ixy="0.0" ixz="0.0" 
                     iyy="0.4" iyz="0.7" izz="0.1"/>
        </inertial>
        <visual >
            <origin xyz="0.0 0.0 -0.050" rpy="0.0 0.0 0.0"/>
            <geometry name="Revlink1">
                <box size="0.080 0.080 0.100"/>
            </geometry>
        </visual>

          
        <collision>
            <origin xyz="0.0 0.0 -0.050" rpy="0.0 0.0 0.0"/>
            <geometry name="Revlink1">
                <box size="0.080 0.080 0.100"/>
               
            </geometry>
        </collision>
    </link>

    <joint name="Mani_J1" type="revolute">
        <origin xyz="0.0 0.0 0.125" rpy="0.0 0.0 0.0"/>
        <parent link="LinearJoint"/>
        <child link="Revlink1"/>
        <axis xyz="0 0 1"/>
        <limit effort="87" lower="-2.8973" upper="2.8973" velocity="2.1750"/>
        <dynamics damping="0.5" friction="0.2"/>
    </joint>

    <link name="Revlink2">
        <inertial>
            <mass value="0.1"/>
            <inertia ixx="0.9" ixy="0.0" ixz="0.0" 
                     iyy="0.4" iyz="0.0" izz="0.9"/>
        </inertial>
        <visual >
            <origin xyz="0.0 0.0 -0.050" rpy="0.0 0.0 0.0"/>
            <geometry name="Revlink2">
                <box size="0.080 0.080 0.100"/>
            </geometry>
        </visual>



        <collision>
            <origin xyz="0.0 0.0 -0.050" rpy="0.0 0.0 0.0"/>
            <geometry name="Revlink2">
                <box size="0.080 0.080 0.100"/>
                
            </geometry>
        </collision>
    </link>

    <joint name="Mani_J2" type="revolute">
        <origin xyz="0.0 0.0 0.100" rpy="0.0 0.0 0.0"/>
        <parent link="Revlink1"/>
        <child link="Revlink2"/>
        <axis xyz="1 0 0"/>
        <limit effort="87" lower="-2.8973" upper="2.8973" velocity="2.1750"/>
        <dynamics damping="0.5" friction="0.2"/>
    </joint>

    <link name="Revlink3">
        <inertial>
            <mass value="0.1"/>
            <inertia ixx="0.9" ixy="0.0" ixz="0.0" 
                     iyy="0.1" iyz="0.5" izz="0.8"/>
        </inertial>
        <visual >
            <origin xyz="-0.175 0.0 0.0" rpy="0.0 1.57 0.0"/>
            <geometry name="Revlink3">
                <box size="0.080 0.080 0.350"/>
            </geometry>
        </visual>



        <collision>
            <origin xyz="-0.175 0.0 0.0" rpy="0.0 1.57 0.0"/>
            <geometry name="Revlink3">
                <box size="0.080 0.080 0.350"/>
            </geometry>
        </collision>
    </link>

    <joint name="Mani_J3" type="revolute">
        <origin xyz="0.0 0.0 0.0" rpy="0.0 0.0 0.0"/>
        <parent link="Revlink2"/>
        <child link="Revlink3"/>
        <axis xyz="0 1 0"/>
        <limit effort="87" lower="-2.8973" upper="2.8973" velocity="2.1750"/>
        <dynamics damping="0.5" friction="0.2"/>
    </joint>

    <link name="Revlink4">
        <inertial>
            <mass value="0.1"/>
            <inertia ixx="0.9" ixy="0.0" ixz="0.0" 
                     iyy="0.1" iyz="0.5" izz="0.8"/>
        </inertial>
        <visual >
            <origin xyz="-0.175 0.0 0.0" rpy="0.0 1.57 0.0"/>
            <geometry name="Revlink4">
                <box size="0.080 0.080 0.350"/>
            </geometry>
        </visual>



        <collision>
            <origin xyz="-0.175 0.0 0.0" rpy="0.0 1.57 0.0"/>
            <geometry name="Revlink4">
                <box size="0.080 0.080 0.350"/>
                
            </geometry>
        </collision>
    </link>

    <joint name="Mani_J4" type="revolute">
        <origin xyz="-0.350 0.0 0.0" rpy="0.0 0.0 0.0"/>
        <parent link="Revlink3"/>
        <child link="Revlink4"/>
        <axis xyz="0 1 0"/>
        <limit effort="87" lower="-2.8973" upper="2.8973" velocity="2.1750"/>
        <dynamics damping="0.5" friction="0.2"/>
    </joint>

    <link name="Revlink5">
        <inertial>
            <mass value="0.1"/>
            <inertia ixx="0.1" ixy="0.0" ixz="0.0" 
                     iyy="0.1" iyz="0.0" izz="0.1"/>
        </inertial>
        <visual >
            <origin xyz="-0.04 0.0 0.0" rpy="0.0 1.57 0.0"/>
            <geometry name="Revlink5">
                <box size="0.080 0.080 0.050"/>
            </geometry>
        </visual>

          
        <collision>
            <origin xyz="-0.175 0.0 0.0" rpy="0.0 1.57 0.0"/>
            <geometry name="Revlink5">
                <box size="0.080 0.080 0.050"/>
            </geometry>
        </collision>
    </link>

    <joint name="Mani_J5" type="revolute">
        <origin xyz="-0.330 0.0 0.0" rpy="0.0 0.0 0.0"/>
        <parent link="Revlink4"/>
        <child link="Revlink5"/>
        <axis xyz="0 1 0"/>
        <limit effort="87" lower="-2.8973" upper="2.8973" velocity="2.1750"/>
        <dynamics damping="0.5" friction="0.2"/>
    </joint>

    <link name="Hand">
        <inertial>
            <mass value="0.05"/>
            <inertia ixx="0.4" ixy="0.0" ixz="0.0" 
                     iyy="0.4" iyz="0.0" izz="0.4"/>
        </inertial>
        <visual >
            <origin xyz="-0.050 0.0 0.0" rpy="0.0 0.0 0.0"/>
            <geometry name="Hand">
                <box size="0.100 0.160 0.095"/>
            </geometry>
        </visual>

        <collision>
            <origin xyz="-0.050 0.0 0.0" rpy="0.0 0.0 0.0"/>
            <geometry name="Hand">
                <box size="0.100 0.160 0.095"/>
                
            </geometry>
        </collision>
    </link>

    <joint name="Mani_J6" type="revolute">
        <origin xyz="-0.07 0.0 0.0" rpy="0.0 0.0 0.0"/>
        <parent link="Revlink5"/>
        <child link="Hand"/>
        <axis xyz="1 0 0"/>
        <limit effort="87" lower="-2.8973" upper="2.8973" velocity="2.1750"/>
        <dynamics damping="0.5" friction="0.2"/>
    </joint>

    <link name="FingerLeft">
        <inertial>
            <mass value="0.05"/>
            <inertia ixx="0.5" ixy="0.0" ixz="0.0" 
                     iyy="0.4" iyz="0.0" izz="0.5"/>
        </inertial>
        <visual>
            <origin xyz = "-0.080 0.0 0.0" rpy="0.0 0.0 0.0"/>
            <geometry name="FingerL">
                <box size="0.160 0.040 0.080"/>
            </geometry>
            <!-- <material name="Red"></material> -->
        </visual>
        <collision>
            <origin xyz = "-0.080 0.0 0.0" rpy="0.0 0.0 0.0"/>
            <geometry name="FingerL">
                <box size="0.160 0.040 0.080"/>
                
            </geometry>
        </collision>
    </link>

    <joint name="FingerL" type="fixed">
        <origin xyz="-0.03 -0.04 0.0" rpy="0.0 0.0 0.0"/>
        <parent link="Hand"/>
        <child link="FingerLeft"/>
        <axis xyz="0 0 1"/>
        <limit effort="87" lower="-2.8973" upper="2.8973" velocity="2.1750"/>
        <dynamics damping="0.5" friction="0.2"/>
    </joint>

    <link name="FingerRight">
        <inertial>
            <mass value="0.05"/>
            <inertia ixx="0.5" ixy="0.0" ixz="0.0" 
                     iyy="0.4" iyz="0.0" izz="0.5"/>
        </inertial>
        <visual>
            <origin xyz = "-0.080 0.0 0.0" rpy="0.0 0.0 0.0"/>
            <geometry name="FingerR">
                <box size="0.160 0.040 0.080"/>
            </geometry>
            <!-- <material name="Red"></material> -->
        </visual>
        <collision>
            <origin xyz = "-0.080 0.0 0.0" rpy="0.0 0.0 0.0"/>
            <geometry name="FingerR">
                <box size="0.160 0.040 0.080"/>
                
            </geometry>
        </collision>
    </link>

    <joint name="FingerR" type="fixed">
        <origin xyz="-0.03 0.04 0.0" rpy="0.0 0.0 0.0"/>
        <parent link="Hand"/>
        <child link="FingerRight"/>
        <axis xyz="0 0 1"/>
        <limit effort="87" lower="-2.8973" upper="2.8973" velocity="2.1750"/>
        <dynamics damping="0.5" friction="0.2"/>
    </joint>

    <link name="HandCamera">
        <inertial>
            <mass value="0.2"/>
            <inertia ixx="0.6" ixy="0.0" ixz="0.0" 
                     iyy="0.1" iyz="0.0" izz="0.1"/>
        </inertial>
        <visual name="Camera">
            <origin xyz="0.0 0.0 0.0" rpy="0.0 0.0 0.0"/>
            <geometry name = "Camera">
                <box size="0.03 0.08 0.03"/>
            </geometry>
            <!-- <material name="black"></material> -->
        </visual>
        <collision>
            <origin xyz="0.0 0.0 0.0" rpy="0.0 0.0 0.0"/>
            <geometry name = "Camera">
                <box size="0.03 0.08 0.03"/>
                
            </geometry>
        </collision>
    </link>

    <joint name="HandCam" type="fixed">
        <origin xyz="-0.02 0.0 0.065" rpy="0.0 0.0 0.0"/>
        <parent link="Hand"/>
        <child link="HandCamera"/>
    </joint> 

    <link name='rgb_cam_camera_link'>
		<visual>
			<origin xyz="0 0 0" rpy="0 0 0"/>
			<geometry>
				<box size="0.01 0.01 0.01"/>
			</geometry>
		</visual>
	</link>

  <joint name="rgb_cam_camera_link_joint" type="fixed">
		<origin rpy="0 0 0" xyz="0.04 0.0 0.2"/>
		<parent link="HandCamera"/>
		<child link="rgb_cam_camera_link"/>
	</joint>


  <link name="rgb_cam_camera_link_frame">
  </link>

  <joint name="rgb_cam_camera_frame_joint" type="fixed">
      <origin xyz="0.01 0 0" rpy="0 0 0" />
      <parent link="rgb_cam_camera_link" />
      <child link="rgb_cam_camera_link_frame" />
      <axis xyz="0 0 0"/>
  </joint>

  <gazebo reference="rgb_cam_camera_link_frame">
    <sensor type="depth" name="rgb_cam">
      <always_on>1</always_on>
      <update_rate>10.0</update_rate>
      <camera name="camera">
          <pose>0 0 0 0 0 0</pose>
          <horizontal_fov>1.3962634</horizontal_fov>
          <image>
            <width>640</width>
            <height>480</height>
            <format>R8G8B8</format>
          </image>
          <clip>
              <near>0.005</near>
              <far>10.0</far>
          </clip>
      </camera>
      <plugin name="camera_controller" filename="libgazebo_ros_camera.so">
          <baseline>0.2</baseline>
          <alwaysOn>true</alwaysOn>
          <updateRate>1.0</updateRate>
          <cameraName>rgb_cam</cameraName>
          <imageTopicName>color/image_raw</imageTopicName>
          <cameraInfoTopicName>color/camera_info</cameraInfoTopicName>
          <frameName>rgb_cam_camera_link_frame</frameName>
          <hackBaseline>0.07</hackBaseline>
      </plugin>
    </sensor>
  </gazebo>
      

    <!-- imu -->
	<!-- <gazebo reference="imu_link">
        <gravity>true</gravity>
        <sensor name="imu_sensor" type="imu">
            <always_on>true</always_on>
            <update_rate>10</update_rate>
            <visualize>true</visualize>
            <topic>__default_topic__</topic>
         <plugin filename="libgazebo_ros_imu_sensor.so" name="imu_plugin">
             <ros>
                 <namespace>/housem8</namespace>
                 <remapping>~/out:=imu</remapping>
               </ros>
         <topicName>imu</topicName>
         <bodyName>imu_link</bodyName>
         <updateRateHZ>10.0</updateRateHZ>
         <gaussianNoise>0.0</gaussianNoise>
         <xyzOffset>0 0 0</xyzOffset>
         <rpyOffset>0 0 0</rpyOffset>
         <frameName>imu_link</frameName>
         <initialOrientationAsReference>false</initialOrientationAsReference>
          </plugin>
             <pose>0 0 0 0 0 0</pose>
         </sensor>
       </gazebo> -->

    <!-- diff_drive -->
  	<gazebo>
        <plugin name='diff_drive' filename="libgazebo_ros_diff_drive.so">
         <updateRate>10</updateRate>
          <left_joint>wheel_left_joint</left_joint>
          <right_joint>wheel_right_joint</right_joint>
          <wheel_separation>0.380</wheel_separation>
          <wheel_diameter>0.200</wheel_diameter>
          <max_wheel_torque>10.0</max_wheel_torque>
          <max_wheel_acceleration>1.0</max_wheel_acceleration>
          <commandTopic>cmd_vel</commandTopic>
          <publish_odom>true</publish_odom>
          <publish_odom_tf>true</publish_odom_tf>
          <publish_wheel_tf>true</publish_wheel_tf>
          <odometry_frame>odom</odometry_frame>
          <robot_base_frame>base_footprint</robot_base_frame>

        </plugin>
      </gazebo>

      
      <!-- hokuyo laser-->
	    <gazebo reference="Lidar_Front">
            <sensor type="ray" name="head_hokuyo_sensor">
                <pose>0 0 0 0 0 0</pose>
                <visualize>True</visualize>
                <always_on>true</always_on>
                <update_rate>40</update_rate>
                <ray>
                    <scan>
                        <horizontal>
                            <samples>720</samples>
                            <resolution>1</resolution>
                            <min_angle>-1.570796</min_angle>
                            <max_angle>1.570796</max_angle>
                        </horizontal>
                    </scan>
                    <range>
                        <min>0.10</min>
                        <max>10.0</max>
                        <resolution>0.01</resolution>
                    </range>
                    <noise>
                        <type>gaussian</type>
                        <mean>0.0</mean>
                        <stddev>0.01</stddev>
                    </noise>
                </ray>
                <plugin name="lidar_controller" filename="libgazebo_ros_ray_sensor.so">
                    <ros>
                        <remapping>~/out:=scan/front</remapping>
                      </ros>
                    <output_type>sensor_msgs/LaserScan</output_type>
                </plugin>
            </sensor>
            </gazebo>
  
    <!-- hokuyo laser-->
    <gazebo reference="Lidar_Back">
        <sensor type="ray" name="head_hokuyo_sensor">
            <pose>0 0 0 0 0 0</pose>
            <visualize>True</visualize>
            <always_on>true</always_on>
            <update_rate>40</update_rate>
            <ray>
                <scan>
                    <horizontal>
                        <samples>720</samples>
                        <resolution>1</resolution>
                        <min_angle>-1.570796</min_angle>
                        <max_angle>1.570796</max_angle>
                    </horizontal>
                </scan>
                <range>
                    <min>0.10</min>
                    <max>10.0</max>
                    <resolution>0.01</resolution>
                </range>
                <noise>
                    <type>gaussian</type>
                    <mean>0.0</mean>
                    <stddev>0.01</stddev>
                </noise>
            </ray>
            <plugin name="lidar_controller" filename="libgazebo_ros_ray_sensor.so">
                <ros>
                    <remapping>~/out:=scan/back</remapping>
                  </ros>
                <output_type>sensor_msgs/LaserScan</output_type>
            </plugin>
        </sensor>
        </gazebo>

    

          
    <!-- Use gazebo_ros_joint_state_publisher instead of publishWheelJointState -->

    <!-- <plugin name="joint_states" filename="libgazebo_ros_joint_state_publisher.so">
        <joint_name>wheel_right_joint</joint_name>
        <joint_name>wheel_left_joint</joint_name>
    </plugin> -->

    <!-- diff_drive -->
  	<!-- <gazebo>
        <plugin name='diff_drive' filename="libgazebo_ros_diff_drive.so">
         <updateRate>100</updateRate>
          <left_joint>wheel_left_joint</left_joint>
          <right_joint>wheel_right_joint</right_joint>
          <wheel_separation>0.380</wheel_separation>
          <wheel_diameter>0.200</wheel_diameter>
          <max_wheel_torque>20</max_wheel_torque>
          <max_wheel_acceleration>10</max_wheel_acceleration>
          <commandTopic>cmd_vel</commandTopic>
          <publish_odom>true</publish_odom>
          <publish_odom_tf>true</publish_odom_tf>
          <publish_wheel_tf>true</publish_wheel_tf>
          <odometry_frame>odom</odometry_frame>
          <robot_base_frame>mobilebaseI</robot_base_frame>
        </plugin>
      </gazebo> -->



</robot>
